2021-08-01 15:27:19,409 [WARNING] django.request: Not Found: /history1/
2021-08-01 16:41:54,376 [ERROR] django.request: Internal Server Error: /auth/login/
Traceback (most recent call last):
  File "c:\users\user\.virtualenvs\quiz-django-xgygd1b9\lib\site-packages\django\core\handlers\exception.py", line 47, in inner
    response = get_response(request)
  File "c:\users\user\.virtualenvs\quiz-django-xgygd1b9\lib\site-packages\django\core\handlers\base.py", line 181, in _get_response
    response = wrapped_callback(request, *callback_args, **callback_kwargs)
  File "C:\Users\User\Desktop\лабы\курсы\dz9\quiz-django\survey_models_django\users\views.py", line 32, in login_user
    user = authenticate(request, username=username, password=password)
  File "c:\users\user\.virtualenvs\quiz-django-xgygd1b9\lib\site-packages\django\views\decorators\debug.py", line 42, in sensitive_variables_wrapper
    return func(*func_args, **func_kwargs)
  File "c:\users\user\.virtualenvs\quiz-django-xgygd1b9\lib\site-packages\django\contrib\auth\__init__.py", line 76, in authenticate
    user = backend.authenticate(request, **credentials)
  File "c:\users\user\.virtualenvs\quiz-django-xgygd1b9\lib\site-packages\django\contrib\auth\backends.py", line 42, in authenticate
    user = UserModel._default_manager.get_by_natural_key(username)
  File "c:\users\user\.virtualenvs\quiz-django-xgygd1b9\lib\site-packages\django\contrib\auth\base_user.py", line 45, in get_by_natural_key
    return self.get(**{self.model.USERNAME_FIELD: username})
  File "c:\users\user\.virtualenvs\quiz-django-xgygd1b9\lib\site-packages\django\db\models\manager.py", line 85, in manager_method
    return getattr(self.get_queryset(), name)(*args, **kwargs)
  File "c:\users\user\.virtualenvs\quiz-django-xgygd1b9\lib\site-packages\django\db\models\query.py", line 431, in get
    num = len(clone)
  File "c:\users\user\.virtualenvs\quiz-django-xgygd1b9\lib\site-packages\django\db\models\query.py", line 262, in __len__
    self._fetch_all()
  File "c:\users\user\.virtualenvs\quiz-django-xgygd1b9\lib\site-packages\django\db\models\query.py", line 1324, in _fetch_all
    self._result_cache = list(self._iterable_class(self))
  File "c:\users\user\.virtualenvs\quiz-django-xgygd1b9\lib\site-packages\django\db\models\query.py", line 51, in __iter__
    results = compiler.execute_sql(chunked_fetch=self.chunked_fetch, chunk_size=self.chunk_size)
  File "c:\users\user\.virtualenvs\quiz-django-xgygd1b9\lib\site-packages\django\db\models\sql\compiler.py", line 1173, in execute_sql
    cursor = self.connection.cursor()
  File "c:\users\user\.virtualenvs\quiz-django-xgygd1b9\lib\site-packages\django\utils\asyncio.py", line 26, in inner
    return func(*args, **kwargs)
  File "c:\users\user\.virtualenvs\quiz-django-xgygd1b9\lib\site-packages\django\db\backends\base\base.py", line 259, in cursor
    return self._cursor()
  File "c:\users\user\.virtualenvs\quiz-django-xgygd1b9\lib\site-packages\django\db\backends\base\base.py", line 235, in _cursor
    self.ensure_connection()
  File "c:\users\user\.virtualenvs\quiz-django-xgygd1b9\lib\site-packages\pytest_django\plugin.py", line 714, in _blocking_wrapper
    raise RuntimeError(
RuntimeError: Database access not allowed, use the "django_db" mark, or the "db" or "transactional_db" fixtures to enable it.
2021-08-01 16:41:55,193 [ERROR] django.request: Internal Server Error: /auth/login/
Traceback (most recent call last):
  File "c:\users\user\.virtualenvs\quiz-django-xgygd1b9\lib\site-packages\django\core\handlers\exception.py", line 47, in inner
    response = get_response(request)
  File "c:\users\user\.virtualenvs\quiz-django-xgygd1b9\lib\site-packages\django\core\handlers\base.py", line 181, in _get_response
    response = wrapped_callback(request, *callback_args, **callback_kwargs)
  File "C:\Users\User\Desktop\лабы\курсы\dz9\quiz-django\survey_models_django\users\views.py", line 32, in login_user
    user = authenticate(request, username=username, password=password)
  File "c:\users\user\.virtualenvs\quiz-django-xgygd1b9\lib\site-packages\django\views\decorators\debug.py", line 42, in sensitive_variables_wrapper
    return func(*func_args, **func_kwargs)
  File "c:\users\user\.virtualenvs\quiz-django-xgygd1b9\lib\site-packages\django\contrib\auth\__init__.py", line 76, in authenticate
    user = backend.authenticate(request, **credentials)
  File "c:\users\user\.virtualenvs\quiz-django-xgygd1b9\lib\site-packages\django\contrib\auth\backends.py", line 42, in authenticate
    user = UserModel._default_manager.get_by_natural_key(username)
  File "c:\users\user\.virtualenvs\quiz-django-xgygd1b9\lib\site-packages\django\contrib\auth\base_user.py", line 45, in get_by_natural_key
    return self.get(**{self.model.USERNAME_FIELD: username})
  File "c:\users\user\.virtualenvs\quiz-django-xgygd1b9\lib\site-packages\django\db\models\manager.py", line 85, in manager_method
    return getattr(self.get_queryset(), name)(*args, **kwargs)
  File "c:\users\user\.virtualenvs\quiz-django-xgygd1b9\lib\site-packages\django\db\models\query.py", line 431, in get
    num = len(clone)
  File "c:\users\user\.virtualenvs\quiz-django-xgygd1b9\lib\site-packages\django\db\models\query.py", line 262, in __len__
    self._fetch_all()
  File "c:\users\user\.virtualenvs\quiz-django-xgygd1b9\lib\site-packages\django\db\models\query.py", line 1324, in _fetch_all
    self._result_cache = list(self._iterable_class(self))
  File "c:\users\user\.virtualenvs\quiz-django-xgygd1b9\lib\site-packages\django\db\models\query.py", line 51, in __iter__
    results = compiler.execute_sql(chunked_fetch=self.chunked_fetch, chunk_size=self.chunk_size)
  File "c:\users\user\.virtualenvs\quiz-django-xgygd1b9\lib\site-packages\django\db\models\sql\compiler.py", line 1173, in execute_sql
    cursor = self.connection.cursor()
  File "c:\users\user\.virtualenvs\quiz-django-xgygd1b9\lib\site-packages\django\utils\asyncio.py", line 26, in inner
    return func(*args, **kwargs)
  File "c:\users\user\.virtualenvs\quiz-django-xgygd1b9\lib\site-packages\django\db\backends\base\base.py", line 259, in cursor
    return self._cursor()
  File "c:\users\user\.virtualenvs\quiz-django-xgygd1b9\lib\site-packages\django\db\backends\base\base.py", line 235, in _cursor
    self.ensure_connection()
  File "c:\users\user\.virtualenvs\quiz-django-xgygd1b9\lib\site-packages\pytest_django\plugin.py", line 714, in _blocking_wrapper
    raise RuntimeError(
RuntimeError: Database access not allowed, use the "django_db" mark, or the "db" or "transactional_db" fixtures to enable it.
2021-08-01 16:42:10,772 [ERROR] django.request: Internal Server Error: /auth/login/
Traceback (most recent call last):
  File "c:\users\user\.virtualenvs\quiz-django-xgygd1b9\lib\site-packages\django\core\handlers\exception.py", line 47, in inner
    response = get_response(request)
  File "c:\users\user\.virtualenvs\quiz-django-xgygd1b9\lib\site-packages\django\core\handlers\base.py", line 181, in _get_response
    response = wrapped_callback(request, *callback_args, **callback_kwargs)
  File "C:\Users\User\Desktop\лабы\курсы\dz9\quiz-django\survey_models_django\users\views.py", line 32, in login_user
    user = authenticate(request, username=username, password=password)
  File "c:\users\user\.virtualenvs\quiz-django-xgygd1b9\lib\site-packages\django\views\decorators\debug.py", line 42, in sensitive_variables_wrapper
    return func(*func_args, **func_kwargs)
  File "c:\users\user\.virtualenvs\quiz-django-xgygd1b9\lib\site-packages\django\contrib\auth\__init__.py", line 76, in authenticate
    user = backend.authenticate(request, **credentials)
  File "c:\users\user\.virtualenvs\quiz-django-xgygd1b9\lib\site-packages\django\contrib\auth\backends.py", line 42, in authenticate
    user = UserModel._default_manager.get_by_natural_key(username)
  File "c:\users\user\.virtualenvs\quiz-django-xgygd1b9\lib\site-packages\django\contrib\auth\base_user.py", line 45, in get_by_natural_key
    return self.get(**{self.model.USERNAME_FIELD: username})
  File "c:\users\user\.virtualenvs\quiz-django-xgygd1b9\lib\site-packages\django\db\models\manager.py", line 85, in manager_method
    return getattr(self.get_queryset(), name)(*args, **kwargs)
  File "c:\users\user\.virtualenvs\quiz-django-xgygd1b9\lib\site-packages\django\db\models\query.py", line 431, in get
    num = len(clone)
  File "c:\users\user\.virtualenvs\quiz-django-xgygd1b9\lib\site-packages\django\db\models\query.py", line 262, in __len__
    self._fetch_all()
  File "c:\users\user\.virtualenvs\quiz-django-xgygd1b9\lib\site-packages\django\db\models\query.py", line 1324, in _fetch_all
    self._result_cache = list(self._iterable_class(self))
  File "c:\users\user\.virtualenvs\quiz-django-xgygd1b9\lib\site-packages\django\db\models\query.py", line 51, in __iter__
    results = compiler.execute_sql(chunked_fetch=self.chunked_fetch, chunk_size=self.chunk_size)
  File "c:\users\user\.virtualenvs\quiz-django-xgygd1b9\lib\site-packages\django\db\models\sql\compiler.py", line 1173, in execute_sql
    cursor = self.connection.cursor()
  File "c:\users\user\.virtualenvs\quiz-django-xgygd1b9\lib\site-packages\django\utils\asyncio.py", line 26, in inner
    return func(*args, **kwargs)
  File "c:\users\user\.virtualenvs\quiz-django-xgygd1b9\lib\site-packages\django\db\backends\base\base.py", line 259, in cursor
    return self._cursor()
  File "c:\users\user\.virtualenvs\quiz-django-xgygd1b9\lib\site-packages\django\db\backends\base\base.py", line 235, in _cursor
    self.ensure_connection()
  File "c:\users\user\.virtualenvs\quiz-django-xgygd1b9\lib\site-packages\pytest_django\plugin.py", line 714, in _blocking_wrapper
    raise RuntimeError(
RuntimeError: Database access not allowed, use the "django_db" mark, or the "db" or "transactional_db" fixtures to enable it.
2021-08-01 16:42:11,692 [ERROR] django.request: Internal Server Error: /auth/login/
Traceback (most recent call last):
  File "c:\users\user\.virtualenvs\quiz-django-xgygd1b9\lib\site-packages\django\core\handlers\exception.py", line 47, in inner
    response = get_response(request)
  File "c:\users\user\.virtualenvs\quiz-django-xgygd1b9\lib\site-packages\django\core\handlers\base.py", line 181, in _get_response
    response = wrapped_callback(request, *callback_args, **callback_kwargs)
  File "C:\Users\User\Desktop\лабы\курсы\dz9\quiz-django\survey_models_django\users\views.py", line 32, in login_user
    user = authenticate(request, username=username, password=password)
  File "c:\users\user\.virtualenvs\quiz-django-xgygd1b9\lib\site-packages\django\views\decorators\debug.py", line 42, in sensitive_variables_wrapper
    return func(*func_args, **func_kwargs)
  File "c:\users\user\.virtualenvs\quiz-django-xgygd1b9\lib\site-packages\django\contrib\auth\__init__.py", line 76, in authenticate
    user = backend.authenticate(request, **credentials)
  File "c:\users\user\.virtualenvs\quiz-django-xgygd1b9\lib\site-packages\django\contrib\auth\backends.py", line 42, in authenticate
    user = UserModel._default_manager.get_by_natural_key(username)
  File "c:\users\user\.virtualenvs\quiz-django-xgygd1b9\lib\site-packages\django\contrib\auth\base_user.py", line 45, in get_by_natural_key
    return self.get(**{self.model.USERNAME_FIELD: username})
  File "c:\users\user\.virtualenvs\quiz-django-xgygd1b9\lib\site-packages\django\db\models\manager.py", line 85, in manager_method
    return getattr(self.get_queryset(), name)(*args, **kwargs)
  File "c:\users\user\.virtualenvs\quiz-django-xgygd1b9\lib\site-packages\django\db\models\query.py", line 431, in get
    num = len(clone)
  File "c:\users\user\.virtualenvs\quiz-django-xgygd1b9\lib\site-packages\django\db\models\query.py", line 262, in __len__
    self._fetch_all()
  File "c:\users\user\.virtualenvs\quiz-django-xgygd1b9\lib\site-packages\django\db\models\query.py", line 1324, in _fetch_all
    self._result_cache = list(self._iterable_class(self))
  File "c:\users\user\.virtualenvs\quiz-django-xgygd1b9\lib\site-packages\django\db\models\query.py", line 51, in __iter__
    results = compiler.execute_sql(chunked_fetch=self.chunked_fetch, chunk_size=self.chunk_size)
  File "c:\users\user\.virtualenvs\quiz-django-xgygd1b9\lib\site-packages\django\db\models\sql\compiler.py", line 1173, in execute_sql
    cursor = self.connection.cursor()
  File "c:\users\user\.virtualenvs\quiz-django-xgygd1b9\lib\site-packages\django\utils\asyncio.py", line 26, in inner
    return func(*args, **kwargs)
  File "c:\users\user\.virtualenvs\quiz-django-xgygd1b9\lib\site-packages\django\db\backends\base\base.py", line 259, in cursor
    return self._cursor()
  File "c:\users\user\.virtualenvs\quiz-django-xgygd1b9\lib\site-packages\django\db\backends\base\base.py", line 235, in _cursor
    self.ensure_connection()
  File "c:\users\user\.virtualenvs\quiz-django-xgygd1b9\lib\site-packages\pytest_django\plugin.py", line 714, in _blocking_wrapper
    raise RuntimeError(
RuntimeError: Database access not allowed, use the "django_db" mark, or the "db" or "transactional_db" fixtures to enable it.
2021-08-01 16:42:43,114 [ERROR] django.request: Internal Server Error: /auth/login/
Traceback (most recent call last):
  File "c:\users\user\.virtualenvs\quiz-django-xgygd1b9\lib\site-packages\django\core\handlers\exception.py", line 47, in inner
    response = get_response(request)
  File "c:\users\user\.virtualenvs\quiz-django-xgygd1b9\lib\site-packages\django\core\handlers\base.py", line 181, in _get_response
    response = wrapped_callback(request, *callback_args, **callback_kwargs)
  File "C:\Users\User\Desktop\лабы\курсы\dz9\quiz-django\survey_models_django\users\views.py", line 32, in login_user
    user = authenticate(request, username=username, password=password)
  File "c:\users\user\.virtualenvs\quiz-django-xgygd1b9\lib\site-packages\django\views\decorators\debug.py", line 42, in sensitive_variables_wrapper
    return func(*func_args, **func_kwargs)
  File "c:\users\user\.virtualenvs\quiz-django-xgygd1b9\lib\site-packages\django\contrib\auth\__init__.py", line 76, in authenticate
    user = backend.authenticate(request, **credentials)
  File "c:\users\user\.virtualenvs\quiz-django-xgygd1b9\lib\site-packages\django\contrib\auth\backends.py", line 42, in authenticate
    user = UserModel._default_manager.get_by_natural_key(username)
  File "c:\users\user\.virtualenvs\quiz-django-xgygd1b9\lib\site-packages\django\contrib\auth\base_user.py", line 45, in get_by_natural_key
    return self.get(**{self.model.USERNAME_FIELD: username})
  File "c:\users\user\.virtualenvs\quiz-django-xgygd1b9\lib\site-packages\django\db\models\manager.py", line 85, in manager_method
    return getattr(self.get_queryset(), name)(*args, **kwargs)
  File "c:\users\user\.virtualenvs\quiz-django-xgygd1b9\lib\site-packages\django\db\models\query.py", line 431, in get
    num = len(clone)
  File "c:\users\user\.virtualenvs\quiz-django-xgygd1b9\lib\site-packages\django\db\models\query.py", line 262, in __len__
    self._fetch_all()
  File "c:\users\user\.virtualenvs\quiz-django-xgygd1b9\lib\site-packages\django\db\models\query.py", line 1324, in _fetch_all
    self._result_cache = list(self._iterable_class(self))
  File "c:\users\user\.virtualenvs\quiz-django-xgygd1b9\lib\site-packages\django\db\models\query.py", line 51, in __iter__
    results = compiler.execute_sql(chunked_fetch=self.chunked_fetch, chunk_size=self.chunk_size)
  File "c:\users\user\.virtualenvs\quiz-django-xgygd1b9\lib\site-packages\django\db\models\sql\compiler.py", line 1173, in execute_sql
    cursor = self.connection.cursor()
  File "c:\users\user\.virtualenvs\quiz-django-xgygd1b9\lib\site-packages\django\utils\asyncio.py", line 26, in inner
    return func(*args, **kwargs)
  File "c:\users\user\.virtualenvs\quiz-django-xgygd1b9\lib\site-packages\django\db\backends\base\base.py", line 259, in cursor
    return self._cursor()
  File "c:\users\user\.virtualenvs\quiz-django-xgygd1b9\lib\site-packages\django\db\backends\base\base.py", line 235, in _cursor
    self.ensure_connection()
  File "c:\users\user\.virtualenvs\quiz-django-xgygd1b9\lib\site-packages\pytest_django\plugin.py", line 714, in _blocking_wrapper
    raise RuntimeError(
RuntimeError: Database access not allowed, use the "django_db" mark, or the "db" or "transactional_db" fixtures to enable it.
2021-08-01 16:42:43,975 [ERROR] django.request: Internal Server Error: /auth/login/
Traceback (most recent call last):
  File "c:\users\user\.virtualenvs\quiz-django-xgygd1b9\lib\site-packages\django\core\handlers\exception.py", line 47, in inner
    response = get_response(request)
  File "c:\users\user\.virtualenvs\quiz-django-xgygd1b9\lib\site-packages\django\core\handlers\base.py", line 181, in _get_response
    response = wrapped_callback(request, *callback_args, **callback_kwargs)
  File "C:\Users\User\Desktop\лабы\курсы\dz9\quiz-django\survey_models_django\users\views.py", line 32, in login_user
    user = authenticate(request, username=username, password=password)
  File "c:\users\user\.virtualenvs\quiz-django-xgygd1b9\lib\site-packages\django\views\decorators\debug.py", line 42, in sensitive_variables_wrapper
    return func(*func_args, **func_kwargs)
  File "c:\users\user\.virtualenvs\quiz-django-xgygd1b9\lib\site-packages\django\contrib\auth\__init__.py", line 76, in authenticate
    user = backend.authenticate(request, **credentials)
  File "c:\users\user\.virtualenvs\quiz-django-xgygd1b9\lib\site-packages\django\contrib\auth\backends.py", line 42, in authenticate
    user = UserModel._default_manager.get_by_natural_key(username)
  File "c:\users\user\.virtualenvs\quiz-django-xgygd1b9\lib\site-packages\django\contrib\auth\base_user.py", line 45, in get_by_natural_key
    return self.get(**{self.model.USERNAME_FIELD: username})
  File "c:\users\user\.virtualenvs\quiz-django-xgygd1b9\lib\site-packages\django\db\models\manager.py", line 85, in manager_method
    return getattr(self.get_queryset(), name)(*args, **kwargs)
  File "c:\users\user\.virtualenvs\quiz-django-xgygd1b9\lib\site-packages\django\db\models\query.py", line 431, in get
    num = len(clone)
  File "c:\users\user\.virtualenvs\quiz-django-xgygd1b9\lib\site-packages\django\db\models\query.py", line 262, in __len__
    self._fetch_all()
  File "c:\users\user\.virtualenvs\quiz-django-xgygd1b9\lib\site-packages\django\db\models\query.py", line 1324, in _fetch_all
    self._result_cache = list(self._iterable_class(self))
  File "c:\users\user\.virtualenvs\quiz-django-xgygd1b9\lib\site-packages\django\db\models\query.py", line 51, in __iter__
    results = compiler.execute_sql(chunked_fetch=self.chunked_fetch, chunk_size=self.chunk_size)
  File "c:\users\user\.virtualenvs\quiz-django-xgygd1b9\lib\site-packages\django\db\models\sql\compiler.py", line 1173, in execute_sql
    cursor = self.connection.cursor()
  File "c:\users\user\.virtualenvs\quiz-django-xgygd1b9\lib\site-packages\django\utils\asyncio.py", line 26, in inner
    return func(*args, **kwargs)
  File "c:\users\user\.virtualenvs\quiz-django-xgygd1b9\lib\site-packages\django\db\backends\base\base.py", line 259, in cursor
    return self._cursor()
  File "c:\users\user\.virtualenvs\quiz-django-xgygd1b9\lib\site-packages\django\db\backends\base\base.py", line 235, in _cursor
    self.ensure_connection()
  File "c:\users\user\.virtualenvs\quiz-django-xgygd1b9\lib\site-packages\pytest_django\plugin.py", line 714, in _blocking_wrapper
    raise RuntimeError(
RuntimeError: Database access not allowed, use the "django_db" mark, or the "db" or "transactional_db" fixtures to enable it.
2021-08-01 17:03:02,309 [ERROR] django.request: Internal Server Error: /start/1/
Traceback (most recent call last):
  File "c:\users\user\.virtualenvs\quiz-django-xgygd1b9\lib\site-packages\django\core\handlers\exception.py", line 47, in inner
    response = get_response(request)
  File "c:\users\user\.virtualenvs\quiz-django-xgygd1b9\lib\site-packages\django\core\handlers\base.py", line 181, in _get_response
    response = wrapped_callback(request, *callback_args, **callback_kwargs)
  File "c:\users\user\.virtualenvs\quiz-django-xgygd1b9\lib\site-packages\django\views\generic\base.py", line 70, in view
    return self.dispatch(request, *args, **kwargs)
  File "c:\users\user\.virtualenvs\quiz-django-xgygd1b9\lib\site-packages\django\views\generic\base.py", line 98, in dispatch
    return handler(request, *args, **kwargs)
  File "C:\Users\User\Desktop\лабы\курсы\dz9\quiz-django\survey_models_django\tests\views.py", line 63, in post
    test = Test.objects.get(pk=kwargs['pk'])
  File "c:\users\user\.virtualenvs\quiz-django-xgygd1b9\lib\site-packages\django\db\models\manager.py", line 85, in manager_method
    return getattr(self.get_queryset(), name)(*args, **kwargs)
  File "c:\users\user\.virtualenvs\quiz-django-xgygd1b9\lib\site-packages\django\db\models\query.py", line 431, in get
    num = len(clone)
  File "c:\users\user\.virtualenvs\quiz-django-xgygd1b9\lib\site-packages\django\db\models\query.py", line 262, in __len__
    self._fetch_all()
  File "c:\users\user\.virtualenvs\quiz-django-xgygd1b9\lib\site-packages\django\db\models\query.py", line 1324, in _fetch_all
    self._result_cache = list(self._iterable_class(self))
  File "c:\users\user\.virtualenvs\quiz-django-xgygd1b9\lib\site-packages\django\db\models\query.py", line 51, in __iter__
    results = compiler.execute_sql(chunked_fetch=self.chunked_fetch, chunk_size=self.chunk_size)
  File "c:\users\user\.virtualenvs\quiz-django-xgygd1b9\lib\site-packages\django\db\models\sql\compiler.py", line 1173, in execute_sql
    cursor = self.connection.cursor()
  File "c:\users\user\.virtualenvs\quiz-django-xgygd1b9\lib\site-packages\django\utils\asyncio.py", line 26, in inner
    return func(*args, **kwargs)
  File "c:\users\user\.virtualenvs\quiz-django-xgygd1b9\lib\site-packages\django\db\backends\base\base.py", line 259, in cursor
    return self._cursor()
  File "c:\users\user\.virtualenvs\quiz-django-xgygd1b9\lib\site-packages\django\db\backends\base\base.py", line 235, in _cursor
    self.ensure_connection()
  File "c:\users\user\.virtualenvs\quiz-django-xgygd1b9\lib\site-packages\pytest_django\plugin.py", line 714, in _blocking_wrapper
    raise RuntimeError(
RuntimeError: Database access not allowed, use the "django_db" mark, or the "db" or "transactional_db" fixtures to enable it.
2021-08-01 17:03:24,536 [ERROR] django.request: Internal Server Error: /start/1/
Traceback (most recent call last):
  File "c:\users\user\.virtualenvs\quiz-django-xgygd1b9\lib\site-packages\django\core\handlers\exception.py", line 47, in inner
    response = get_response(request)
  File "c:\users\user\.virtualenvs\quiz-django-xgygd1b9\lib\site-packages\django\core\handlers\base.py", line 181, in _get_response
    response = wrapped_callback(request, *callback_args, **callback_kwargs)
  File "c:\users\user\.virtualenvs\quiz-django-xgygd1b9\lib\site-packages\django\views\generic\base.py", line 70, in view
    return self.dispatch(request, *args, **kwargs)
  File "c:\users\user\.virtualenvs\quiz-django-xgygd1b9\lib\site-packages\django\views\generic\base.py", line 98, in dispatch
    return handler(request, *args, **kwargs)
  File "C:\Users\User\Desktop\лабы\курсы\dz9\quiz-django\survey_models_django\tests\views.py", line 63, in post
    test = Test.objects.get(pk=kwargs['pk'])
  File "c:\users\user\.virtualenvs\quiz-django-xgygd1b9\lib\site-packages\django\db\models\manager.py", line 85, in manager_method
    return getattr(self.get_queryset(), name)(*args, **kwargs)
  File "c:\users\user\.virtualenvs\quiz-django-xgygd1b9\lib\site-packages\django\db\models\query.py", line 435, in get
    raise self.model.DoesNotExist(
tests.models.Test.DoesNotExist: Test matching query does not exist.
2021-08-01 17:03:55,216 [ERROR] django.request: Internal Server Error: /start/1/
Traceback (most recent call last):
  File "c:\users\user\.virtualenvs\quiz-django-xgygd1b9\lib\site-packages\django\core\handlers\exception.py", line 47, in inner
    response = get_response(request)
  File "c:\users\user\.virtualenvs\quiz-django-xgygd1b9\lib\site-packages\django\core\handlers\base.py", line 181, in _get_response
    response = wrapped_callback(request, *callback_args, **callback_kwargs)
  File "c:\users\user\.virtualenvs\quiz-django-xgygd1b9\lib\site-packages\django\views\generic\base.py", line 70, in view
    return self.dispatch(request, *args, **kwargs)
  File "c:\users\user\.virtualenvs\quiz-django-xgygd1b9\lib\site-packages\django\views\generic\base.py", line 98, in dispatch
    return handler(request, *args, **kwargs)
  File "C:\Users\User\Desktop\лабы\курсы\dz9\quiz-django\survey_models_django\tests\views.py", line 63, in post
    test = Test.objects.get(pk=kwargs['pk'])
  File "c:\users\user\.virtualenvs\quiz-django-xgygd1b9\lib\site-packages\django\db\models\manager.py", line 85, in manager_method
    return getattr(self.get_queryset(), name)(*args, **kwargs)
  File "c:\users\user\.virtualenvs\quiz-django-xgygd1b9\lib\site-packages\django\db\models\query.py", line 435, in get
    raise self.model.DoesNotExist(
tests.models.Test.DoesNotExist: Test matching query does not exist.
2021-08-01 17:06:49,927 [ERROR] django.request: Internal Server Error: /
Traceback (most recent call last):
  File "c:\users\user\.virtualenvs\quiz-django-xgygd1b9\lib\site-packages\django\core\handlers\exception.py", line 47, in inner
    response = get_response(request)
  File "c:\users\user\.virtualenvs\quiz-django-xgygd1b9\lib\site-packages\django\core\handlers\base.py", line 204, in _get_response
    response = response.render()
  File "c:\users\user\.virtualenvs\quiz-django-xgygd1b9\lib\site-packages\django\template\response.py", line 105, in render
    self.content = self.rendered_content
  File "c:\users\user\.virtualenvs\quiz-django-xgygd1b9\lib\site-packages\django\template\response.py", line 83, in rendered_content
    return template.render(context, self._request)
  File "c:\users\user\.virtualenvs\quiz-django-xgygd1b9\lib\site-packages\django\template\backends\django.py", line 61, in render
    return self.template.render(context)
  File "c:\users\user\.virtualenvs\quiz-django-xgygd1b9\lib\site-packages\django\template\base.py", line 170, in render
    return self._render(context)
  File "c:\users\user\.virtualenvs\quiz-django-xgygd1b9\lib\site-packages\django\test\utils.py", line 100, in instrumented_test_render
    return self.nodelist.render(context)
  File "c:\users\user\.virtualenvs\quiz-django-xgygd1b9\lib\site-packages\django\template\base.py", line 938, in render
    bit = node.render_annotated(context)
  File "c:\users\user\.virtualenvs\quiz-django-xgygd1b9\lib\site-packages\django\template\base.py", line 905, in render_annotated
    return self.render(context)
  File "c:\users\user\.virtualenvs\quiz-django-xgygd1b9\lib\site-packages\django\template\loader_tags.py", line 150, in render
    return compiled_parent._render(context)
  File "c:\users\user\.virtualenvs\quiz-django-xgygd1b9\lib\site-packages\django\test\utils.py", line 100, in instrumented_test_render
    return self.nodelist.render(context)
  File "c:\users\user\.virtualenvs\quiz-django-xgygd1b9\lib\site-packages\django\template\base.py", line 938, in render
    bit = node.render_annotated(context)
  File "c:\users\user\.virtualenvs\quiz-django-xgygd1b9\lib\site-packages\django\template\base.py", line 905, in render_annotated
    return self.render(context)
  File "c:\users\user\.virtualenvs\quiz-django-xgygd1b9\lib\site-packages\django\template\loader_tags.py", line 62, in render
    result = block.nodelist.render(context)
  File "c:\users\user\.virtualenvs\quiz-django-xgygd1b9\lib\site-packages\django\template\base.py", line 938, in render
    bit = node.render_annotated(context)
  File "c:\users\user\.virtualenvs\quiz-django-xgygd1b9\lib\site-packages\django\template\base.py", line 905, in render_annotated
    return self.render(context)
  File "c:\users\user\.virtualenvs\quiz-django-xgygd1b9\lib\site-packages\django\template\defaulttags.py", line 312, in render
    return nodelist.render(context)
  File "c:\users\user\.virtualenvs\quiz-django-xgygd1b9\lib\site-packages\django\template\base.py", line 938, in render
    bit = node.render_annotated(context)
  File "c:\users\user\.virtualenvs\quiz-django-xgygd1b9\lib\site-packages\django\template\base.py", line 905, in render_annotated
    return self.render(context)
  File "c:\users\user\.virtualenvs\quiz-django-xgygd1b9\lib\site-packages\django\template\defaulttags.py", line 168, in render
    len_values = len(values)
  File "c:\users\user\.virtualenvs\quiz-django-xgygd1b9\lib\site-packages\django\db\models\query.py", line 262, in __len__
    self._fetch_all()
  File "c:\users\user\.virtualenvs\quiz-django-xgygd1b9\lib\site-packages\django\db\models\query.py", line 1324, in _fetch_all
    self._result_cache = list(self._iterable_class(self))
  File "c:\users\user\.virtualenvs\quiz-django-xgygd1b9\lib\site-packages\django\db\models\query.py", line 51, in __iter__
    results = compiler.execute_sql(chunked_fetch=self.chunked_fetch, chunk_size=self.chunk_size)
  File "c:\users\user\.virtualenvs\quiz-django-xgygd1b9\lib\site-packages\django\db\models\sql\compiler.py", line 1173, in execute_sql
    cursor = self.connection.cursor()
  File "c:\users\user\.virtualenvs\quiz-django-xgygd1b9\lib\site-packages\django\utils\asyncio.py", line 26, in inner
    return func(*args, **kwargs)
  File "c:\users\user\.virtualenvs\quiz-django-xgygd1b9\lib\site-packages\django\db\backends\base\base.py", line 259, in cursor
    return self._cursor()
  File "c:\users\user\.virtualenvs\quiz-django-xgygd1b9\lib\site-packages\django\db\backends\base\base.py", line 235, in _cursor
    self.ensure_connection()
  File "c:\users\user\.virtualenvs\quiz-django-xgygd1b9\lib\site-packages\pytest_django\plugin.py", line 714, in _blocking_wrapper
    raise RuntimeError(
RuntimeError: Database access not allowed, use the "django_db" mark, or the "db" or "transactional_db" fixtures to enable it.
2021-08-01 17:19:48,066 [INFO] django.utils.autoreload: Watching for file changes with StatReloader
2021-08-01 17:20:33,294 [INFO] django.utils.autoreload: C:\Users\User\Desktop\лабы\курсы\dz9\quiz-django\survey_models_django\tests_app\apps.py changed, reloading.
2021-08-01 17:20:33,804 [INFO] django.utils.autoreload: Watching for file changes with StatReloader
2021-08-01 17:20:40,759 [INFO] django.utils.autoreload: Watching for file changes with StatReloader
2021-08-01 17:25:55,629 [INFO] django.utils.autoreload: Watching for file changes with StatReloader
2021-08-01 17:26:19,525 [INFO] django.utils.autoreload: C:\Users\User\Desktop\лабы\курсы\dz9\quiz-django\survey_models_django\tests_app\migrations\0009_test_created_at.py changed, reloading.
2021-08-01 17:26:20,046 [INFO] django.utils.autoreload: Watching for file changes with StatReloader
2021-08-01 17:26:29,579 [INFO] django.utils.autoreload: C:\Users\User\Desktop\лабы\курсы\dz9\quiz-django\survey_models_django\tests_app\migrations\0008_auto_20210720_1052.py changed, reloading.
2021-08-01 17:26:30,162 [INFO] django.utils.autoreload: Watching for file changes with StatReloader
2021-08-01 17:26:33,557 [INFO] django.utils.autoreload: C:\Users\User\Desktop\лабы\курсы\dz9\quiz-django\survey_models_django\tests_app\migrations\0007_alter_testrun_finished_at.py changed, reloading.
2021-08-01 17:26:34,226 [INFO] django.utils.autoreload: Watching for file changes with StatReloader
2021-08-01 17:26:36,634 [INFO] django.utils.autoreload: C:\Users\User\Desktop\лабы\курсы\dz9\quiz-django\survey_models_django\tests_app\migrations\0006_auto_20210719_1526.py changed, reloading.
2021-08-01 17:26:37,153 [INFO] django.utils.autoreload: Watching for file changes with StatReloader
2021-08-01 17:26:42,685 [INFO] django.utils.autoreload: C:\Users\User\Desktop\лабы\курсы\dz9\quiz-django\survey_models_django\tests_app\migrations\0005_auto_20210719_0235.py changed, reloading.
2021-08-01 17:26:43,187 [INFO] django.utils.autoreload: Watching for file changes with StatReloader
2021-08-01 17:26:50,709 [INFO] django.utils.autoreload: C:\Users\User\Desktop\лабы\курсы\dz9\quiz-django\survey_models_django\tests_app\migrations\0004_auto_20210718_2041.py changed, reloading.
2021-08-01 17:26:51,224 [INFO] django.utils.autoreload: Watching for file changes with StatReloader
2021-08-01 17:26:55,642 [INFO] django.utils.autoreload: C:\Users\User\Desktop\лабы\курсы\dz9\quiz-django\survey_models_django\tests_app\migrations\0003_auto_20210718_1836.py changed, reloading.
2021-08-01 17:26:56,196 [INFO] django.utils.autoreload: Watching for file changes with StatReloader
2021-08-01 17:26:58,568 [INFO] django.utils.autoreload: C:\Users\User\Desktop\лабы\курсы\dz9\quiz-django\survey_models_django\tests_app\migrations\0002_testrun_points.py changed, reloading.
2021-08-01 17:26:59,424 [INFO] django.utils.autoreload: Watching for file changes with StatReloader
2021-08-01 17:27:20,142 [WARNING] django.request: Not Found: /dishes/
2021-08-01 17:27:20,143 [WARNING] django.server: "GET /dishes/ HTTP/1.1" 404 3090
2021-08-01 17:27:20,304 [WARNING] django.request: Not Found: /favicon.ico
2021-08-01 17:27:20,305 [WARNING] django.server: "GET /favicon.ico HTTP/1.1" 404 3102
2021-08-01 17:27:26,450 [WARNING] django.request: Not Found: /dishes/
2021-08-01 17:27:26,450 [WARNING] django.server: "GET /dishes/ HTTP/1.1" 404 3090
2021-08-01 17:27:32,504 [INFO] django.server: "GET / HTTP/1.1" 200 9884
2021-08-01 17:27:32,543 [INFO] django.server: "GET /static/css/base.css HTTP/1.1" 304 0
2021-08-01 17:27:32,543 [INFO] django.server: "GET /static/css/register.css HTTP/1.1" 304 0
2021-08-01 17:27:32,548 [INFO] django.server: "GET /static/css/table.css HTTP/1.1" 304 0
2021-08-01 17:27:32,890 [WARNING] django.request: Not Found: /favicon.ico
2021-08-01 17:27:32,890 [WARNING] django.server: "GET /favicon.ico HTTP/1.1" 404 3102
2021-08-01 17:27:44,324 [INFO] django.server: "GET /?search=fac&from_date=&to_date= HTTP/1.1" 200 8291
2021-08-01 17:42:49,595 [INFO] django.utils.autoreload: Watching for file changes with StatReloader
2021-08-01 17:44:24,007 [INFO] django.utils.autoreload: Watching for file changes with StatReloader
2021-08-01 17:44:37,427 [INFO] django.server: "GET /?search=fac&from_date=&to_date= HTTP/1.1" 200 8291
2021-08-01 17:44:40,921 [INFO] django.server: "GET /1/ HTTP/1.1" 200 5257
2021-08-01 17:44:42,535 [INFO] django.server: "GET /start/1/ HTTP/1.1" 200 13155
2021-08-01 17:44:50,108 [INFO] django.server: "POST /start/1/ HTTP/1.1" 302 0
2021-08-01 17:44:50,132 [INFO] django.server: "GET / HTTP/1.1" 200 9884
2021-08-01 17:44:52,567 [INFO] django.server: "GET /history/1/ HTTP/1.1" 200 6995
2021-08-01 17:44:59,057 [INFO] django.server: "GET / HTTP/1.1" 200 9884
2021-08-01 17:52:00,470 [INFO] django.utils.autoreload: Watching for file changes with StatReloader
